Workbook

Sheet Sales
A1: PRODUCT NAME | B1: Unit Rate (â‚¹) | C1: Wk1 (Feb3) | D1: Wk2 (Feb10) | E1: Wk3 (Feb17) | F1: Wk4 (Feb24) | G1: Wk5 (Mar3) | H1: Wk6 (Mar10) | I1: Wk7 (Mar17) | J1: Wk8 (Mar24) | K1: Wk9 (Mar31) | L1: Wk10 (Apr7) | M1: Wk11 (Apr14) | N1: Wk12 (Apr20) | O1: Total
A2: Ladies' Suit (Pcs.) | B2: 1800 | C2: 5 | D2: 4 | E2: 4 | F2: 5 | G2: 6 | H2: 5 | I2: 7 | J2: 8 | K2: 7 | L2: 9 | M2: 8 | N2: 9 | O2: =SUM(C2:N2) -> 77
A3: Men's Shirt (Pcs.) | B3: 799 | C3: 0 | D3: 1 | E3: 1 | F3: 2 | G3: 1 | H3: 0 | I3: 1 | J3: 0 | K3: 2 | L3: 1 | M3: 0 | N3: 1 | O3: =SUM(C3:N3) -> 10
A4: Ladies Slippers (Pairs) | B4: 499 | C4: 8 | D4: 7 | E4: 5 | F4: 7 | G4: 9 | H4: 8 | I4: 10 | J4: 6 | K4: 9 | L4: 7 | M4: 8 | N4: 9 | O4: =SUM(C4:N4) -> 93
A5: Dish Soap Bar (Pcs.) | B5: 60 | C5: 6 | D5: 3 | E5: 4 | F5: 5 | G5: 6 | H5: 4 | I5: 5 | J5: 3 | K5: 4 | L5: 5 | M5: 3 | N5: 4 | O5: =SUM(C5:N5) -> 52
A6: Bizz Detergent Powder (Pkt.) | B6: 460 | C6: 5 | D6: 1 | E6: 3 | F6: 4 | G6: 5 | H6: 2 | I6: 6 | J6: 4 | K6: 3 | L6: 4 | M6: 2 | N6: 5 | O6: =SUM(C6:N6) -> 44
A7: Amla Candy (200gm) (Pkt.) | B7: 160 | C7: 11 | D7: 3 | E7: 5 | F7: 7 | G7: 9 | H7: 6 | I7: 8 | J7: 5 | K7: 7 | L7: 6 | M7: 5 | N7: 7 | O7: =SUM(C7:N7) -> 79
A8: Green Tea (20 bags) (Pkt.) | B8: 260 | C8: 2 | D8: 2 | E8: 3 | F8: 1 | G8: 2 | H8: 1 | I8: 3 | J8: 2 | K8: 1 | L8: 2 | M8: 1 | N8: 2 | O8: =SUM(C8:N8) -> 22
A9: Coconut Oil (175ml) (Pcs.) | B9: 100 | C9: 8 | D9: 3 | E9: 9 | F9: 6 | G9: 7 | H9: 5 | I9: 8 | J9: 4 | K9: 6 | L9: 5 | M9: 4 | N9: 6 | O9: =SUM(C9:N9) -> 71
A10: Atta Noodles (Pkt.) | B10: 40 | C10: 12 | D10: 13 | E10: 14 | F10: 15 | G10: 18 | H10: 19 | I10: 20 | J10: 17 | K10: 15 | L10: 13 | M10: 12 | N10: 13 | O10: =SUM(C10:N10) -> 181
A11: Coconut Biscuits (Pkt.) | B11: 40 | C11: 8 | D11: 10 | E11: 9 | F11: 11 | G11: 10 | H11: 12 | I11: 11 | J11: 10 | K11: 9 | L11: 10 | M11: 11 | N11: 10 | O11: =SUM(C11:N11) -> 121
A12: Aaloo Bhujia (Pkt.) | B12: 110 | C12: 11 | D12: 5 | E12: 6 | F12: 7 | G12: 10 | H12: 6 | I12: 12 | J12: 8 | K12: 9 | L12: 7 | M12: 6 | N12: 8 | O12: =SUM(C12:N12) -> 95
A13: Red Chilli Powder (100gm) (Pkt.) | B13: 50 | C13: 8 | D13: 2 | E13: 8 | F13: 5 | G13: 7 | H13: 10 | I13: 6 | J13: 4 | K13: 5 | L13: 4 | M13: 3 | N13: 5 | O13: =SUM(C13:N13) -> 67
... A22: Liquid Handwash (200ml) (Pcs.) | B22: 80 | C22: 10 | D22: 2 | E22: 7 | F22: 6 | G22: 9 | H22: 5 | I22: 8 | J22: 4 | K22: 7 | L22: 6 | M22: 5 | N22: 7 | O22: =SUM(C22:N22) -> 76
A23: Total | C23: =sum(C2:C22) -> 113 | D23: =SUM(D2:D22) -> 76 | E23: =SUM(E2:E22) -> 104 | F23: =SUM(F2:F22) -> 100 | G23: =SUM(G2:G22) -> 117 | H23: =SUM(H2:H22) -> 94 | I23: =SUM(I2:I22) -> 128 | J23: =SUM(J2:J22) -> 88 | K23: =SUM(K2:K22) -> 100 | ... N23: =SUM(N2:N22) -> 102 | O23: =SUM(C23:N23) -> 1195

Sheet Revenue
A1: PRODUCT NAME | B1: Opening Balance(in Rs.) | C1: Sale | D1: Sale Return | E1: Purchase
A2: Ladies' Suit (Pcs.) | B2: 10810 | C2: 77 | D2: 3
A3: Men's Shirt (Pcs.) | B3: 2875 | C3: 10
A4: Ladies Slippers (Pairs) | B4: 14835 | C4: 93 | E4: 29
A5: Dish Soap Bar (Pcs.) | B5: 17940 | C5: 52 | E5: 67
A6: Bizz Detergent Powder (Pkt.) | B6: 15870 | C6: 44 | D6: 6
A7: Amla Candy (200gm) (Pkt.) | B7: 9200 | C7: 79 | D7: 11
A8: Green Tea (20 bags) (Pkt.) | B8: 9890 | C8: 22 | E8: 19
A9: Coconut Oil (175ml) (Pcs.) | B9: 9660 | C9: 71 | E9: 11
A10: Atta Noodles (Pkt.) | B10: 15180 | C10: 181
A11: Coconut Biscuits (Pkt.) | B11: 14720 | C11: 121 | E11: 32
A12: Aaloo Bhujia (Pkt.) | B12: 12075 | C12: 95
A13: Red Chilli Powder (100gm) (Pkt.) | B13: 16215 | C13: 67
A14: Chaat Masala (100gm) (Pkt.) | B14: 12535 | C14: 32
A15: Jasmine Soap (Pcs.) | B15: 17940 | C15: 46 | E15: 43
A16: Nutricharge Woman (Pkt.) | B16: 23795 | C16: 15
A17: Gamma Oryzanol (Pcs.) | B17: 11495 | C17: 1
A18: Nutricharge Bioage (Pcs.) | B18: 15840 | C18: 4
A19: Nutricharge Veg Omega (Pcs.) | B19: 22760 | C19: 3
A20: Rice Bran Oil (Lts.) | B20: 11500 | C20: 40
A21: Pasta (Pkt.) | B21: 10465 | C21: 66
A22: Liquid Handwash (200ml) (Pcs.) | B22: 11615 | C22: 76
B23: =SUM(B2:B22) -> 287215 | C23: =SUM(C2:C22) -> 1195 | D23: =SUM(D2:D22) -> 20 | E23: =SUM(E2:E22) -> 201

Sheet Weekly Revenue Data
A1: Week | B1: Total Sale Amount | C1: Account | D1: Cash Balance
A2: 1 | B2: =SUMPRODUCT(Sales!B2:B22, Sales!C2:C22) -> 24252 | C2: 3132 | D2: =B2-C2 -> 21120
A3: 2 | B3: =SUMPRODUCT(Sales!B2:B22, Sales!D2:D22) -> 17752 | C3: 2123 | D3: =B3-C3 -> 15629
A4: 3 | B4: =SUMPRODUCT(Sales!B2:B22, Sales!E2:E22) -> 19974 | C4: 5643 | D4: =B4-C4 -> 14331
A5: 4 | B5: =SUMPRODUCT(Sales!B2:B22, Sales!F2:F22) -> 24531 | C5: 3445 | D5: =B5-C5 -> 21086
A6: 5 | B6: =SUMPRODUCT(Sales!B2:B22, Sales!G2:G22) -> 29430 | C6: 4345 | D6: =B6-C6 -> 25085
A7: 6 | B7: =SUMPRODUCT(Sales!B2:B22, Sales!H2:H22) -> 19912 | C7: 1234 | D7: =B7-C7 -> 18678
A8: 7 | B8: =SUMPRODUCT(Sales!B2:B22, Sales!I2:I22) -> 30469 | C8: 5455 | D8: =B8-C8 -> 25014
A9: 8 | B9: =SUMPRODUCT(Sales!B2:B22, Sales!J2:J22) -> 25044 | C9: 2344 | D9: =B9-C9 -> 22700
A10: 9 | B10: =SUMPRODUCT(Sales!B2:B22, Sales!K2:K22) -> 26759 | C10: 1544 | D10: =B10-C10 -> 25215
A11: 10 | B11: =SUMPRODUCT(Sales!B10:B28, Sales!K10:K28) -> 4470 | C11: 788 | D11: =B11-C11 -> 3682
A12: 11 | B12: =SUMPRODUCT(Sales!B2:B22, Sales!M2:M22) -> 26262 | C12: 3245 | D12: =B12-C12 -> 23017
A13: 12 | B13: =SUMPRODUCT(Sales!B2:B22, Sales!N2:N22) -> 30590 | C13: 2709 | D13: =B13-C13 -> 27881

Sheet Calculations
A3: Name of the Item | B3: Total Sale | C3: Max Sale | D3: Min Sale | E3: Revenue Generated (Rate * Total sale) | F3: Average Weekly Sales | G3: Average Price | H3: Average Weekly Revenue
A4: Ladies' Suit (Pcs.) | B4: =(SUM(Sales!C2:N2)) -> 77 | C4: =MAX(Sales!C2:N2) -> 9 | D4: =MIN(Sales!C2:N2) -> 4 | E4: =Sales!B2*Calculations!B4 -> 138600 | F4: =AVERAGE(Sales!C2:N2) -> 6.4166667 | G4: =Sales!B2 -> 1800 | H4: =AVERAGE(Sales!C2:N2) * Sales!B2 -> 11550 | J4: Week | K4: Total Weekly Sales | M4: Name of the Item | N4: Revenue Generated
A5: Men's Shirt (Pcs.) | B5: =(SUM(Sales!C3:N3)) -> 10 | C5: =MAX(Sales!C3:N3) -> 2 | D5: =MIN(Sales!C3:N3) -> 0 | E5: =Sales!B3*Calculations!B5 -> 7990 | F5: =AVERAGE(Sales!C3:N3) -> 0.83333333 | G5: =Sales!B3 -> 799 | H5: =AVERAGE(Sales!C3:N3) * Sales!B3 -> 665.83333 | J5: 1 | K5: =sum(Sales!C2:Sales!C22) -> 113 | M5: Ladies' Suit | N5: =LARGE(E4:E24,1) -> 138600
A6: Ladies Slippers (Pairs) | B6: =(SUM(Sales!C4:N4)) -> 93 | C6: =MAX(Sales!C4:N4) -> 10 | D6: =MIN(Sales!C4:N4) -> 5 | E6: =Sales!B4*Calculations!B6 -> 46407 | F6: =AVERAGE(Sales!C4:N4) -> 7.75 | G6: =Sales!B4 -> 499 | H6: =AVERAGE(Sales!C4:N4) * Sales!B4 -> 3867.25 | J6: 2 | K6: =sum(Sales!D2:Sales!D22) -> 76 | M6: Ladies Slippers (Pairs) | N6: =LARGE(E4:E24,2) -> 46407 | S6: Week | T6: Sales | V6: Week | W6: Sales
A7: Dish Soap Bar (Pcs.) | B7: =(SUM(Sales!C5:N5)) -> 52 | C7: =MAX(Sales!C5:N5) -> 6 | D7: =MIN(Sales!C5:N5) -> 3 | E7: =Sales!B5*Calculations!B7 -> 3120 | F7: =AVERAGE(Sales!C5:N5) -> 4.3333333 | G7: =Sales!B5 -> 60 | H7: =AVERAGE(Sales!C5:N5) * Sales!B5 -> 260 | J7: 3 | K7: =sum(Sales!E2:Sales!E22) -> 104 | M7: Bizz Detergent Powder (Pkt.) | N7: =LARGE(E4:E24,3) -> 20240 | S7: 1 | T7: 12 | V7: 1 | W7: 0
A8: Bizz Detergent Powder (Pkt.) | B8: =(SUM(Sales!C6:N6)) -> 44 | C8: =MAX(Sales!C6:N6) -> 6 | D8: =MIN(Sales!C6:N6) -> 1 | E8: =Sales!B6*Calculations!B8 -> 20240 | F8: =AVERAGE(Sales!C6:N6) -> 3.6666667 | G8: =Sales!B6 -> 460 | H8: =AVERAGE(Sales!C6:N6) * Sales!B6 -> 1686.6667 | J8: 4 | K8: =sum(Sales!F2:Sales!F22) -> 100 | M8: Amla Candy (200gm) (Pkt.) | N8: =LARGE(E4:E24,4) -> 12640 | S8: 2 | T8: 13 | V8: 2 | W8: 1
A9: Amla Candy (200gm) (Pkt.) | B9: =(SUM(Sales!C7:N7)) -> 79 | C9: =MAX(Sales!C7:N7) -> 11 | D9: =MIN(Sales!C7:N7) -> 3 | E9: =Sales!B7*Calculations!B9 -> 12640 | F9: =AVERAGE(Sales!C7:N7) -> 6.5833333 | G9: =Sales!B7 -> 160 | H9: =AVERAGE(Sales!C7:N7) * Sales!B7 -> 1053.3333 | J9: 5 | K9: =sum(Sales!G2:Sales!G22) -> 117 | P9: Week | Q9: Sales | S9: 3 | T9: 14 | V9: 3 | W9: 1
A10: Green Tea (20 bags) (Pkt.) | B10: =(SUM(Sales!C8:N8)) -> 22 | C10: =MAX(Sales!C8:N8) -> 3 | D10: =MIN(Sales!C8:N8) -> 1 | E10: =Sales!B8*Calculations!B10 -> 5720 | F10: =AVERAGE(Sales!C8:N8) -> 1.8333333 | G10: =Sales!B8 -> 260 | H10: =AVERAGE(Sales!C8:N8) * Sales!B8 -> 476.66667 | J10: 6 | K10: =sum(Sales!H2:Sales!H22) -> 94 | P10: 1 | Q10: 11 | S10: 4 | T10: 15 | V10: 4 | W10: 2
A11: Coconut Oil (175ml) (Pcs.) | B11: =(SUM(Sales!C9:N9)) -> 71 | C11: =MAX(Sales!C9:N9) -> 9 | D11: =MIN(Sales!C9:N9) -> 3 | E11: =Sales!B9*Calculations!B11 -> 7100 | F11: =AVERAGE(Sales!C9:N9) -> 5.9166667 | G11: =Sales!B9 -> 100 | H11: =AVERAGE(Sales!C9:N9) * Sales!B9 -> 591.66667 | J11: 7 | K11: =sum(Sales!I2:Sales!I22) -> 128 | M11: Name of the Item | N11: Total Sale | P11: 2 | Q11: 3 | S11: 5 | T11: 18 | V11: 5 | W11: 1
A12: Atta Noodles (Pkt.) | B12: =(SUM(Sales!C10:N10)) -> 181 | C12: =MAX(Sales!C10:N10) -> 20 | D12: =MIN(Sales!C10:N10) -> 12 | E12: =Sales!B10*Calculations!B12 -> 7240 | F12: =AVERAGE(Sales!C10:N10) -> 15.083333 | G12: =Sales!B10 -> 40 | H12: =AVERAGE(Sales!C10:N10) * Sales!B10 -> 603.33333 | J12: 8 | K12: =sum(Sales!J2:Sales!J22) -> 88 | M12: Gamma Oryzanol (Pcs.) | N12: =SMALL(B4:B24,1) -> 1 | P12: 3 | Q12: 5 | S12: 6 | T12: 19 | V12: 6 | W12: 0
A13: Coconut Biscuits (Pkt.) | B13: =(SUM(Sales!C11:N11)) -> 121 | C13: =MAX(Sales!C11:N11) -> 12 | D13: =MIN(Sales!C11:N11) -> 8 | E13: =Sales!B11*Calculations!B13 -> 4840 | F13: =AVERAGE(Sales!C11:N11) -> 10.083333 | G13: =Sales!B11 -> 40 | H13: =AVERAGE(Sales!C11:N11) * Sales!B11 -> 403.33333 | J13: 9 | K13: =sum(Sales!K2:Sales!K22) -> 100 | M13: Nutricharge Veg Omega (Pcs.) | N13: =SMALL(B4:B24,2) -> 3 | P13: 4 | Q13: 7 | S13: 7 | T13: 20 | V13: 7 | W13: 1
A14: Aaloo Bhujia (Pkt.) | B14: =(SUM(Sales!C12:N12)) -> 95 | C14: =MAX(Sales!C12:N12) -> 12 | D14: =MIN(Sales!C12:N12) -> 5 | E14: =Sales!B12*Calculations!B14 -> 10450 | F14: =AVERAGE(Sales!C12:N12) -> 7.9166667 | G14: =Sales!B12 -> 110 | H14: =AVERAGE(Sales!C12:N12) * Sales!B12 -> 870.83333 | J14: 10 | K14: =sum(Sales!L2:Sales!L22) -> 93 | M14: Nutricharge Bioage (Pcs.) | N14: =SMALL(B4:B24,3) -> 4 | P14: 5 | Q14: 9 | S14: 8 | T14: 17 | V14: 8 | W14: 0
A15: Red Chilli Powder (100gm) (Pkt.) | B15: =(SUM(Sales!C13:N13)) -> 67 | C15: =MAX(Sales!C13:N13) -> 10 | D15: =MIN(Sales!C13:N13) -> 2 | E15: =Sales!B13*Calculations!B15 -> 3350 | F15: =AVERAGE(Sales!C13:N13) -> 5.5833333 | G15: =Sales!B13 -> 50 | H15: =AVERAGE(Sales!C13:N13) * Sales!B13 -> 279.16667 | J15: 11 | K15: =sum(Sales!M2:Sales!M22) -> 80 | M15: Men's Shirt (Pcs.) | N15: =SMALL(B4:B24,4) -> 10 | P15: 6 | Q15: 6 | S15: 9 | T15: 15 | V15: 9 | W15: 2
A16: Chaat Masala (100gm) (Pkt.) | B16: =(SUM(Sales!C14:N14)) -> 32 | C16: =MAX(Sales!C14:N14) -> 6 | D16: =MIN(Sales!C14:N14) -> 0 | E16: =Sales!B14*Calculations!B16 -> 1920 | F16: =AVERAGE(Sales!C14:N14) -> 2.6666667 | G16: =Sales!B14 -> 60 | H16: =AVERAGE(Sales!C14:N14) * Sales!B14 -> 160 | J16: 12 | K16: =sum(Sales!N2:Sales!N22) -> 102 | P16: 7 | Q16: 8 | S16: 10 | T16: 13 | V16: 10 | W16: 1
A17: Jasmine Soap (Pcs.) | B17: =(SUM(Sales!C15:N15)) -> 46 | C17: =MAX(Sales!C15:N15) -> 6 | D17: =MIN(Sales!C15:N15) -> 2 | E17: =Sales!B15*Calculations!B17 -> 3680 | F17: =AVERAGE(Sales!C15:N15) -> 3.8333333 | G17: =Sales!B15 -> 80 | H17: =AVERAGE(Sales!C15:N15) * Sales!B15 -> 306.66667 | P17: 8 | Q17: 5 | S17: 11 | T17: 12 | V17: 11 | W17: 0
A18: Nutricharge Woman (Pkt.) | B18: =(SUM(Sales!C16:N16)) -> 15 | C18: =MAX(Sales!C16:N16) -> 3 | D18: =MIN(Sales!C16:N16) -> 0 | E18: =Sales!B16*Calculations!B18 -> 7350 | F18: =AVERAGE(Sales!C16:N16) -> 1.25 | G18: =Sales!B16 -> 490 | H18: =AVERAGE(Sales!C16:N16) * Sales!B16 -> 612.5 | M18: Name of the Item | N18: Revenue Generated | P18: 9 | Q18: 7 | S18: 12 | T18: 13 | V18: 12 | W18: 1
A19: Gamma Oryzanol (Pcs.) | B19: =(SUM(Sales!C17:N17)) -> 1 | C19: =MAX(Sales!C17:N17) -> 1 | D19: =MIN(Sales!C17:N17) -> 0 | E19: =Sales!B17*Calculations!B19 -> 570 | F19: =AVERAGE(Sales!C17:N17) -> 0.083333333 | G19: =Sales!B17 -> 570 | H19: =AVERAGE(Sales!C17:N17) * Sales!B17 -> 47.5 | J19: Name of the Item | K19: Total Sale | M19: Gamma Oryzanol (Pcs.) | N19: =SMALL(E4:E24,1) -> 570 | P19: 10 | Q19: 6
A20: Nutricharge Bioage (Pcs.) | B20: =(SUM(Sales!C18:N18)) -> 4 | C20: =MAX(Sales!C18:N18) -> 2 | D20: =MIN(Sales!C18:N18) -> 0 | E20: =Sales!B18*Calculations!B20 -> 6000 | F20: =AVERAGE(Sales!C18:N18) -> 0.33333333 | G20: =Sales!B18 -> 1500 | H20: =AVERAGE(Sales!C18:N18) * Sales!B18 -> 500 | J20: Atta Noodles (Pkt.) | K20: =LARGE(B4:B24,1) -> 181 | M20: Nutricharge Veg Omega (Pcs.) | N20: =SMALL(E4:E24,2) -> 1380 | P20: 11 | Q20: 5 | S20: R-squared | T20: =RSQ(Aata_Noodles_Sales_Trend[Sales], Aata_Noodles_Sales_Trend[Week]) -> 0.0010088047 | V20: R-squared | W20: =RSQ(Men_Shirt_trend_analysis[Sales], Men_Shirt_trend_analysis[Week]) -> 0
A21: Nutricharge Veg Omega (Pcs.) | B21: =(SUM(Sales!C19:N19)) -> 3 | C21: =MAX(Sales!C19:N19) -> 1 | D21: =MIN(Sales!C19:N19) -> 0 | E21: =Sales!B19*Calculations!B21 -> 1380 | F21: =AVERAGE(Sales!C19:N19) -> 0.25 | G21: =Sales!B19 -> 460 | H21: =AVERAGE(Sales!C19:N19) * Sales!B19 -> 115 | J21: Coconut Biscuits (Pkt.) | K21: =LARGE(B4:B24,2) -> 121 | M21: Chaat Masala (100gm) (Pkt.) | N21: =SMALL(E4:E24,3) -> 1920 | P21: 12 | Q21: 7 | S21: T-test | T21: =_xlfn.T.TEST(T7:T12, T13:T18, 2, 3) -> 0.9230218
A22: Rice Bran Oil (Lts.) | B22: =(SUM(Sales!C20:N20)) -> 40 | C22: =MAX(Sales!C20:N20) -> 5 | D22: =MIN(Sales!C20:N20) -> 1 | E22: =Sales!B20*Calculations!B22 -> 4800 | F22: =AVERAGE(Sales!C20:N20) -> 3.3333333 | G22: =Sales!B20 -> 120 | H22: =AVERAGE(Sales!C20:N20) * Sales!B20 -> 400 | J22: Aaloo Bhujia (Pkt.) | K22: =LARGE(B4:B24,3) -> 95 | M22: Dish Soap Bar (Pcs.) | N22: =SMALL(E4:E24,4) -> 3120
A23: Pasta (Pkt.) | B23: =(SUM(Sales!C21:N21)) -> 66 | C23: =MAX(Sales!C21:N21) -> 11 | D23: =MIN(Sales!C21:N21) -> 2 | E23: =Sales!B21*Calculations!B23 -> 3960 | F23: =AVERAGE(Sales!C21:N21) -> 5.5 | G23: =Sales!B21 -> 60 | H23: =AVERAGE(Sales!C21:N21) * Sales!B21 -> 330 | J23: Ladies Slippers (Pairs) | K23: =LARGE(B4:B24,4) -> 93 | P23: Return Rate | Q23: =IF(Revenue!C7=0, "",Revenue!D7/Revenue!C7)*100 -> 13.924051
A24: Liquid Handwash (200ml) (Pcs.) | B24: =(SUM(Sales!C22:N22)) -> 76 | C24: =MAX(Sales!C22:N22) -> 10 | D24: =MIN(Sales!C22:N22) -> 2 | E24: =Sales!B22*Calculations!B24 -> 6080 | F24: =AVERAGE(Sales!C22:N22) -> 6.3333333 | G24: =Sales!B22 -> 80 | H24: =AVERAGE(Sales!C22:N22) * Sales!B22 -> 506.66667 | J24: Others | K24: =B25-SUM(K20:K23) -> 705
A25: Total | B25: =SUM(B4:B24) -> 1195 | E25: =SUM(E4:E24) -> 303437 | G25: =Sales!B23 | H25: =AVERAGE(Sales!C23:N23) * Sales!B23 -> 0 | R25: PRODUCT NAME | S25: Zero Count | T25: Sporadic Demand
A26: Mean | F26: =AVERAGE(F4:F24) -> 4.7420635 | G26: =AVERAGE(G4:G24) -> 371.33333 | H26: =AVERAGE(H4:H24) -> 1204.1151 | R26: Ladies' Suit (Pcs.) | S26: =COUNTIF(Sales!C2:N2,0) -> 0 | T26: =IF(S26>=3,1,0) -> 0
A27: Std Dev | F27: =_xlfn.STDEV.P(F4:F24) -> 3.5968189 | G27: =_xlfn.STDEV.P(G4:G24) -> 469.49541 | H27: =_xlfn.STDEV.P(H4:H24) -> 2445.6161 | R27: Men's Shirt (Pcs.) | S27: =COUNTIF(Sales!C3:N3,0) -> 4 | T27: =IF(S27>=3,1,0) -> 1
A28: CV | F28: =_xlfn.STDEV.P(F4:F24)/AVERAGE(F4:F24)*100 -> 75.849236 | G28: =_xlfn.STDEV.P(G4:G24)/AVERAGE(G4:G24)*100 -> 126.43503 | H28: =_xlfn.STDEV.P(H4:H24)/AVERAGE(H4:H24)*100 -> 203.10485 | J28: Metric | K28: Value | M28: Metric | N28: Value | R28: Ladies Slippers (Pairs) | S28: =COUNTIF(Sales!C4:N4,0) -> 0 | T28: =IF(S28>=3,1,0) -> 0
J29: Min Weekly Revenue | K29: =MIN('Weekly Revenue Data'!B2:B13) -> 4470 | M29: Mean Weekly Revenue | N29: =AVERAGE('Weekly Revenue Data'!B2:B13) -> 23287.083 | R29: Dish Soap Bar (Pcs.) | S29: =COUNTIF(Sales!C5:N5,0) -> 0 | T29: =IF(S29>=3,1,0) -> 0
J30: Max Weekly Revenue | K30: =MAX('Weekly Revenue Data'!B2:B13) -> 30590 | M30: Std Dev Weekly Revenue | N30: =_xlfn.STDEV.P('Weekly Revenue Data'!B2:B13) -> 6929.4355 | R30: Bizz Detergent Powder (Pkt.) | S30: =COUNTIF(Sales!C6:N6,0) -> 0 | T30: =IF(S30>=3,1,0) -> 0
J31: Max Weekly Variation (%) | K31: =(K30-K29)/K29*100 -> 584.34004 | M31: CV Weekly Revenue (%) | N31: =_xlfn.STDEV.P('Weekly Revenue Data'!B2:B13)/AVERAGE('Weekly Revenue Data'!B2:B13)*100 -> 29.756562 | R31: Amla Candy (200gm) (Pkt.) | S31: =COUNTIF(Sales!C7:N7,0) -> 0 | T31: =IF(S31>=3,1,0) -> 0
A32: Name of the Item | B32: Total Sale | C32: Revenue Generated | D32: Cummulative Value | E32: Cumulative % | F32: ABC Category | J32: February Revenue | K32: =SUM('Weekly Revenue Data'!B2:B5) -> 86509 | M32: Max Weekly Revenue | N32: =MAX('Weekly Revenue Data'!B2:B13) -> 30590 | R32: Green Tea (20 bags) (Pkt.) | S32: =COUNTIF(Sales!C8:N8,0) -> 0 | T32: =IF(S32>=3,1,0) -> 0
A33: Ladies' Suit (Pcs.) | B33: 77 | C33: 138600 | D33: =C33 -> 138600 | E33: =D33 / SUM($C$33:$C$53) -> 0.45676697 | F33: =IF(E33<=0.8,"A",IF(E33<=0.95,"B","C")) -> A | J33: March Revenue | K33: =SUM('Weekly Revenue Data'!B6:B9) -> 104855 | M33: Min Weekly Revenue | N33: =MIN('Weekly Revenue Data'!B2:B13) -> 4470 | R33: Coconut Oil (175ml) (Pcs.) | S33: =COUNTIF(Sales!C9:N9,0) -> 0 | T33: =IF(S33>=3,1,0) -> 0
A34: Ladies Slippers (Pairs) | B34: 93 | C34: 46407 | D34: =C34+D33 -> 185007 | E34: =D34 / SUM($C$33:$C$53) -> 0.60970482 | F34: =IF(E34<=0.8,"A",IF(E34<=0.95,"B","C")) -> A | J34: April Revenue | K34: =SUM('Weekly Revenue Data'!B10:B13) -> 88081 | M34: Max Weekly Fluctuation (%) | N34: =(K30-K29)/K29*100 -> 584.34004 | R34: Atta Noodles (Pkt.) | S34: =COUNTIF(Sales!C10:N10,0) -> 0 | T34: =IF(S34>=3,1,0) -> 0
A35: Bizz Detergent Powder (Pkt.) | B35: 44 | C35: 20240 | D35: =C35+D34 -> 205247 | E35: =D35 / SUM($C$33:$C$53) -> 0.67640729 | F35: =IF(E35<=0.8,"A",IF(E35<=0.95,"B","C")) -> A | J35: March Growth over Feb (%) | K35: =(K33-K32)/K33*100 -> 17.496543 | M35: Total Zero Sales Instances | N35: =SUM(S26:S46) -> 37 | R35: Coconut Biscuits (Pkt.) | S35: =COUNTIF(Sales!C11:N11,0) -> 0 | T35: =IF(S35>=3,1,0) -> 0
A36: Amla Candy (200gm) (Pkt.) | B36: 79 | C36: 12640 | D36: =C36+D35 -> 217887 | E36: =D36 / SUM($C$33:$C$53) -> 0.71806339 | F36: =IF(E36<=0.8,"A",IF(E36<=0.95,"B","C")) -> A | J36: April Decline over Mar (%) | K36: =(K34 - K33)/K33*100 -> -15.99733 | M36: Products with ≥3 Zero Sales Weeks | N36: =SUM(T26:T46) -> 4 | R36: Aaloo Bhujia (Pkt.) | S36: =COUNTIF(Sales!C12:N12,0) -> 0 | T36: =IF(S36>=3,1,0) -> 0
A37: Aaloo Bhujia (Pkt.) | B37: 95 | C37: 10450 | D37: =C37+D36 -> 228337 | E37: =D37 / SUM($C$33:$C$53) -> 0.75250217 | F37: =IF(E37<=0.8,"A",IF(E37<=0.95,"B","C")) -> A | J37: Min Weekly Units Sold | K37: =MIN(Sales!C23:N23) -> 76 | M37: Number of Products for 80% Revenue | N37: =MATCH(0.8, Table2[Cumulative %], 1) -> 6 | R37: Red Chilli Powder (100gm) (Pkt.) | S37: =COUNTIF(Sales!C13:N13,0) -> 0 | T37: =IF(S37>=3,1,0) -> 0
A38: Men's Shirt (Pcs.) | B38: 10 | C38: 7990 | D38: =C38+D37 -> 236327 | E38: =D38 / SUM($C$33:$C$53) -> 0.77883383 | F38: =IF(E38<=0.8,"A",IF(E38<=0.95,"B","C")) -> A | J38: Max Weekly Units Sold | K38: =MAX(Sales!C23:N23) -> 128 | M38: % Revenue by Top Products | N38: {=SUM(C33 :INDEX(Table2[Revenue Generated ], N37))/SUM(Table2[Revenue Generated ])*100} -> 77.883383 | R38: Chaat Masala (100gm) (Pkt.) | S38: =COUNTIF(Sales!C14:N14,0) -> 2 | T38: =IF(S38>=3,1,0) -> 0
A39: Nutricharge Woman (Pkt.) | B39: 15 | C39: 7350 | D39: =C39+D38 -> 243677 | E39: =D39 / SUM($C$33:$C$53) -> 0.80305632 | F39: =IF(E39<=0.8,"A",IF(E39<=0.95,"B","C")) -> B | J39: Avg Weekly Units Sold | K39: =AVERAGE(Sales!C23:N23) -> 99.583333 | R39: Jasmine Soap (Pcs.) | S39: =COUNTIF(Sales!C15:N15,0) -> 0 | T39: =IF(S39>=3,1,0) -> 0
A40: Atta Noodles (Pkt.) | B40: 181 | C40: 7240 | D40: =C40+D39 -> 250917 | E40: =D40 / SUM($C$33:$C$53) -> 0.8269163 | F40: =IF(E40<=0.8,"A",IF(E40<=0.95,"B","C")) -> B | R40: Nutricharge Woman (Pkt.) | S40: =COUNTIF(Sales!C16:N16,0) -> 2 | T40: =IF(S40>=3,1,0) -> 0
A41: Coconut Oil (175ml) (Pcs.) | B41: 71 | C41: 7100 | D41: =C41+D40 -> 258017 | E41: =D41 / SUM($C$33:$C$53) -> 0.85031489 | F41: =IF(E41<=0.8,"A",IF(E41<=0.95,"B","C")) -> B | R41: Gamma Oryzanol (Pcs.) | S41: =COUNTIF(Sales!C17:N17,0) -> 11 | T41: =IF(S41>=3,1,0) -> 1
A42: Liquid Handwash (200ml) (Pcs.) | B42: 76 | C42: 6080 | D42: =C42+D41 -> 264097 | E42: =D42 / SUM($C$33:$C$53) -> 0.870352 | F42: =IF(E42<=0.8,"A",IF(E42<=0.95,"B","C")) -> B | H42: Week | I42: Revenue | J42: Sales | R42: Nutricharge Bioage (Pcs.) | S42: =COUNTIF(Sales!C18:N18,0) -> 9 | T42: =IF(S42>=3,1,0) -> 1
...

Sheet Visuals
